Workbook

Sheet Blad1
A1: Personeelsnummer | B1: Achternaam | C1: Voornaam | D1: Wekenteller | E1: Schaal | F1: Uurloon incl. ATV | G1: Uurloon excl. ATV | H1: 1 | I1: 1.33 | J1: 1.35 | K1: 1.8 | L1: 2 | M1: 1.4 | N1: 1.8 | O1: 2
B2: Cimoszko | C2: Adam | E2: D0 | F2: 16.79 | G2: 15.82 | H2: 31.57 | I2: 40.24 | J2: 40.77 | K2: 52.59 | L2: 56.32 | M2: 30.02 | N2: 38.59 | O2: 42.88 | Q2: =G2*1.7058 -> 26.985756
A3: 374420 | B3: Cwioro | C3: Agnieszka | D3: 222 | E3: A4 | F3: 16.14 | G3: 15.209197 | H3: 29.616158 | I3: 37.617176 | J3: 38.102086 | K3: 49.012564 | L3: 52.463414 | M3: 27.463551 | N3: 35.31028 | O3: 39.233645 | Q3: =H2-Q2 -> 4.584244 | R3: MARGE
A4: 349489 | B4: Kosior | C4: Agnieszka | D4: 3 | E4: A0 | F4: 15.35 | G4: 14.47 | H4: 29.123375 | I4: 37.04683 | J4: 37.52704 | K4: 48.331751 | L4: 53.133845 | M4: 27.453642 | N4: 35.297539 | O4: 39.219488
B5: Rogalska | C5: Agnieszka | E5: A0 | F5: 15.35 | G5: 14.47 | H5: 29.123375 | I5: 37.04683 | J5: 37.52704 | K5: 48.331751 | L5: 53.133845 | M5: 27.453642 | N5: 35.297539 | O5: 39.219488 | Q5: =0.33 * 1.5695 * 14.47 -> 7.4945195
A6: 379930 | B6: Ziolkowska | C6: Agnieszka | D6: 103 | E6: A2 | F6: 15.75 | G6: 14.841689 | H6: 29.8721 | I6: 37.942778 | J6: 38.43191 | K6: 49.43738 | L6: 52.918274 | M6: 27.826385 | N6: 35.776781 | O6: 39.751979 | Q6: =I2-H2 -> 8.67
A7: 438333 | B7: Garcia Ocampo | C7: Alejandro | E7: A0 | F7: 15.35 | G7: 14.47 | H7: 29.123375 | I7: 37.04683 | J7: 37.52704 | K7: 48.331751 | L7: 53.133845 | M7: 27.453642 | N7: 35.297539 | O7: 39.219488
A8: 438061 | B8: Ciszewska | C8: Aleksandra | E8: A0 | F8: 15.35 | G8: 14.47 | H8: 29.123375 | I8: 37.04683 | J8: 37.52704 | K8: 48.331751 | L8: 53.133845 | M8: 27.453642 | N8: 35.297539 | O8: 39.219488
A9: 438252 | B9: Spataru | C9: Alexandru | E9: A0 | F9: 15.35 | G9: 14.47 | H9: 29.123375 | I9: 37.04683 | J9: 37.52704 | K9: 48.331751 | L9: 53.133845 | M9: 27.453642 | N9: 35.297539 | O9: 39.219488
A10: 438639 | B10: Ionas | C10: Alin | E10: A0 | F10: 15.35 | G10: 14.47 | H10: 29.123375 | I10: 37.04683 | J10: 37.52704 | K10: 48.331751 | L10: 53.133845 | M10: 27.453642 | N10: 35.297539 | O10: 39.219488
A11: 409766 | B11: Calzado Marin | C11: Alvaro | D11: 50 | E11: C1 | F11: 16.58 | G11: 15.623822 | H11: 31.21745 | I11: 39.775814 | J11: 40.294503 | K11: 51.964999 | L11: 55.656233 | M11: 29.642765 | N11: 38.112127 | O11: 42.346807
A12: 375350 | B12: Jankowski | C12: Andrzej | D12: 13 | E12: B6 | F12: 17.27 | G12: 16.274029 | H12: 32.392175 | I12: 41.306707 | J12: 41.846982 | K12: 54.003162 | L12: 57.848012 | M12: 30.876391 | N12: 39.698216 | O12: 44.109129
A13: 438313 | B13: Damaso Gonzalez | C13: Angel | E13: A0 | F13: 15.35 | G13: 14.47 | H13: 29.123375 | I13: 37.04683 | J13: 37.52704 | K13: 48.331751 | L13: 53.133845 | M13: 27.453642 | N13: 35.297539 | O13: 39.219488
A14: 374795 | B14: Cyran | C14: Anna | D14: 71 | E14: A1 | F14: 15.55 | G14: 14.653223 | H14: 29.53074 | I14: 37.498933 | J14: 37.981854 | K14: 48.847572 | L14: 52.284264 | M14: 27.473034 | N14: 35.322473 | O14: 39.247192
A15: 374953 | B15: Gajewska | C15: Anna | D15: 307 | E15: B3 | F15: 16.63 | G15: 15.670939 | H15: 30.424511 | I15: 38.668434 | J15: 39.168066 | K15: 50.40978 | L15: 53.965395 | M15: 28.297327 | N15: 36.382278 | O15: 40.424753
A16: 367459 | B16: Kulak | C16: Anna | D16: 88 | E16: A2 | F16: 15.75 | G16: 14.841689 | H16: 29.8721 | I16: 37.942778 | J16: 38.43191 | K16: 49.43738 | L16: 52.918274 | M16: 27.826385 | N16: 35.776781 | O16: 39.751979
A17: 385246 | B17: Mikulska | C17: Anna | D17: 23 | E17: A0 | F17: 15.35 | G17: 14.47 | H17: 29.123375 | I17: 37.04683 | J17: 37.52704 | K17: 48.331751 | L17: 53.133845 | M17: 27.453642 | N17: 35.297539 | O17: 39.219488
A18: 421717 | B18: Recka | C18: Anna | E18: A0 | F18: 15.35 | G18: 14.47 | H18: 29.123375 | I18: 37.04683 | J18: 37.52704 | K18: 48.331751 | L18: 53.133845 | M18: 27.453642 | N18: 35.297539 | O18: 39.219488
A19: 438239 | B19: Manuca | C19: Antonio | E19: A0 | F19: 15.35 | G19: 14.47 | H19: 29.123375 | I19: 37.04683 | J19: 37.52704 | K19: 48.331751 | L19: 53.133845 | M19: 27.453642 | N19: 35.297539 | O19: 39.219488
A20: 438076 | B20: Koralewski | C20: Arkadiusz | E20: A0 | F20: 15.35 | G20: 14.47 | H20: 29.123375 | I20: 37.04683 | J20: 37.52704 | K20: 48.331751 | L20: 53.133845 | M20: 27.453642 | N20: 35.297539 | O20: 39.219488
A21: 410631 | B21: Bisliukas | C21: Armandas | D21: 47 | E21: C1 | F21: 16.58 | G21: 15.623822 | H21: 31.21745 | I21: 39.775814 | J21: 40.294503 | K21: 51.964999 | L21: 55.656233 | M21: 29.642765 | N21: 38.112127 | O21: 42.346807
A22: 401068 | B22: Holubowska | C22: Barbara | D22: 55 | E22: A1 | F22: 15.55 | G22: 14.653223 | H22: 29.53074 | I22: 37.498933 | J22: 37.981854 | K22: 48.847572 | L22: 52.284264 | M22: 27.473034 | N22: 35.322473 | O22: 39.247192
A23: 399664 | B23: Baraniuk | C23: Beata | E23: A0 | F23: 15.35 | G23: 14.47 | H23: 29.123375 | I23: 37.04683 | J23: 37.52704 | K23: 48.331751 | L23: 53.133845 | M23: 27.453642 | N23: 35.297539 | O23: 39.219488
A24: 374549 | B24: Marczak | C24: Beata | D24: 159 | E24: A3 | F24: 15.95 | G24: 15.030155 | H24: 30.21346 | I24: 38.386623 | J24: 38.881966 | K24: 50.027188 | L24: 54.98062 | M24: 28.179736 | N24: 36.231089 | O24: 40.256766
A25: 374526 | B25: Mlynarczyk | C25: Bogumil | D25: 216 | E25: B3 | F25: 16.63 | G25: 15.670939 | H25: 30.424511 | I25: 38.668434 | J25: 39.168066 | K25: 50.40978 | L25: 53.965395 | M25: 28.297327 | N25: 36.382278 | O25: 40.424753
A26: 408119 | B26: Hanus | C26: Branislav | D26: 26 | E26: C0 | F26: 16.34 | G26: 15.397663 | H26: 30.80885 | I26: 39.243329 | J26: 39.75451 | K26: 51.256072 | L26: 54.893875 | M26: 29.213678 | N26: 37.560443 | O26: 41.733826
A27: 429524 | B27: Filipek | C27: Damian | E27: A0 | F27: 15.35 | G27: 14.47 | H27: 29.123375 | I27: 37.04683 | J27: 37.52704 | K27: 48.331751 | L27: 53.133845 | M27: 27.453642 | N27: 35.297539 | O27: 39.219488
A28: 333051 | B28: Motyka | C28: Damian | E28: A0 | F28: 15.35 | G28: 14.47 | H28: 29.123375 | I28: 37.04683 | J28: 37.52704 | K28: 48.331751 | L28: 53.133845 | M28: 27.453642 | N28: 35.297539 | O28: 39.219488
A29: 429618 | B29: Ferradas Echevarria | C29: Daniel | D29: 14 | E29: B0 | F29: 15.98 | G29: 15.058424 | H29: 30.19595 | I29: 38.444602 | J29: 38.944521 | K29: 50.192683 | L29: 53.750337 | M29: 28.570047 | N29: 36.732918 | O29: 40.814354
A30: 438671 | B30: Lopez Ventura | C30: Daniel | E30: A0 | F30: 15.35 | G30: 14.47 | H30: 29.123375 | I30: 37.04683 | J30: 37.52704 | K30: 48.331751 | L30: 53.133845 | M30: 27.453642 | N30: 35.297539 | O30: 39.219488
A31: 420508 | B31: Pikta | C31: Daniel | D31: 13 | E31: C0 | F31: 16.34 | G31: 15.397663 | H31: 30.80885 | I31: 39.243329 | J31: 39.75451 | K31: 51.256072 | L31: 54.893875 | M31: 29.213678 | N31: 37.560443 | O31: 41.733826
A32: 408973 | B32: Wilczak | C32: Daniel | E32: A0 | F32: 15.35 | G32: 14.47 | H32: 29.123375 | I32: 37.04683 | J32: 37.52704 | K32: 48.331751 | L32: 53.133845 | M32: 27.453642 | N32: 35.297539 | O32: 39.219488
A33: 421890 | B33: Adamska | C33: Daria | D33: 25 | E33: A0 | F33: 15.35 | G33: 14.47 | H33: 29.123375 | I33: 37.04683 | J33: 37.52704 | K33: 48.331751 | L33: 53.133845 | M33: 27.453642 | N33: 35.297539 | O33: 39.219488
A34: 429728 | B34: Major | C34: Daria | D34: 3 | E34: A0 | F34: 15.35 | G34: 14.47 | H34: 29.123375 | I34: 37.04683 | J34: 37.52704 | K34: 48.331751 | L34: 53.133845 | M34: 27.453642 | N34: 35.297539 | O34: 39.219488
A35: 374814 | B35: Glabien | C35: Dariusz | D35: 267 | E35: B6 | F35: 17.27 | G35: 16.274029 | H35: 31.480319 | I35: 40.041507 | J35: 40.560367 | K35: 52.234714 | L35: 55.927166 | M35: 29.38634 | N35: 37.782438 | O35: 41.980486
A36: 422226 | B36: Babics | C36: David | D36: 26 | E36: A0 | F36: 15.35 | G36: 14.47 | H36: 29.123375 | I36: 37.04683 | J36: 37.52704 | K36: 48.331751 | L36: 53.133845 | M36: 27.453642 | N36: 35.297539 | O36: 39.219488
A37: 434089 | B37: Ciz | C37: David | D37: 4 | E37: A0 | F37: 15.35 | G37: 14.47 | H37: 29.123375 | I37: 37.04683 | J37: 37.52704 | K37: 48.331751 | L37: 53.133845 | M37: 27.453642 | N37: 35.297539 | O37: 39.219488
A38: 374801 | B38: Kutermak | C38: Dawid | D38: 187 | E38: C3 | F38: 17.03 | G38: 16.04787 | H38: 32.056804 | I38: 40.783385 | J38: 41.312268 | K38: 53.212151 | L38: 56.975937 | M38: 30.087831 | N38: 38.684354 | O38: 42.982616
A39: 351945 | B39: Szpakowski | C39: Dawid | D39: 95 | E39: B2 | F39: 16.41 | G39: 15.463626 | H39: 30.998588 | I39: 39.407466 | J39: 39.917095 | K39: 51.383746 | L39: 55.010507 | M39: 28.992443 | N39: 37.275998 | O39: 41.417776
A40: 429551 | B40: Kijak | C40: Dominik | D40: 5 | E40: A0 | F40: 15.35 | G40: 14.47 | H40: 29.123375 | I40: 37.04683 | J40: 37.52704 | K40: 48.331751 | L40: 53.133845 | M40: 27.453642 | N40: 35.297539 | O40: 39.219488
...

Sheet unique_names
B2: {=_xlfn._xlws.SORT(_xlfn.UNIQUE(G2:G231))} | G2: =_xlfn.TEXTJOIN(" ", TRUE, Blad1!B2:C2) -> Cimoszko Adam
B3: Adamska Daria | G3: =_xlfn.TEXTJOIN(" ", TRUE, Blad1!B3:C3) -> Cwioro Agnieszka
B4: Andryjanczyk Przemyslaw | G4: =_xlfn.TEXTJOIN(" ", TRUE, Blad1!B4:C4) -> Kosior Agnieszka
B5: Arhipova Inna | G5: =_xlfn.TEXTJOIN(" ", TRUE, Blad1!B5:C5) -> Rogalska Agnieszka
B6: Babics David | G6: =_xlfn.TEXTJOIN(" ", TRUE, Blad1!B6:C6) -> Ziolkowska Agnieszka
B7: Baraniuk Beata | G7: =_xlfn.TEXTJOIN(" ", TRUE, Blad1!B7:C7) -> Garcia Ocampo Alejandro
B8: Baselga Alvarez de Lorenzana Lucia | G8: =_xlfn.TEXTJOIN(" ", TRUE, Blad1!B8:C8) -> Ciszewska Aleksandra
B9: Bender Kinga | G9: =_xlfn.TEXTJOIN(" ", TRUE, Blad1!B9:C9) -> Spataru Alexandru
B10: Bierczak Piotr | G10: =_xlfn.TEXTJOIN(" ", TRUE, Blad1!B10:C10) -> Ionas Alin
B11: Bisliukas Armandas | G11: =_xlfn.TEXTJOIN(" ", TRUE, Blad1!B11:C11) -> Calzado Marin Alvaro
B12: Calzado Marin Alvaro | G12: =_xlfn.TEXTJOIN(" ", TRUE, Blad1!B12:C12) -> Jankowski Andrzej
B13: Chlipala Marzena | G13: =_xlfn.TEXTJOIN(" ", TRUE, Blad1!B13:C13) -> Damaso Gonzalez Angel
B14: Chwalinska Izabela | G14: =_xlfn.TEXTJOIN(" ", TRUE, Blad1!B14:C14) -> Cyran Anna
... B140: Ziolkowska Agnieszka | G140: =_xlfn.TEXTJOIN(" ", TRUE, Blad1!B140:C140)
G141: =_xlfn.TEXTJOIN(" ", TRUE, Blad1!B141:C141)
G142: =_xlfn.TEXTJOIN(" ", TRUE, Blad1!B142:C142)
G143: =_xlfn.TEXTJOIN(" ", TRUE, Blad1!B143:C143)
G144: =_xlfn.TEXTJOIN(" ", TRUE, Blad1!B144:C144)
G145: =_xlfn.TEXTJOIN(" ", TRUE, Blad1!B145:C145)
G146: =_xlfn.TEXTJOIN(" ", TRUE, Blad1!B146:C146)
G147: =_xlfn.TEXTJOIN(" ", TRUE, Blad1!B147:C147)
G148: =_xlfn.TEXTJOIN(" ", TRUE, Blad1!B148:C148)
G149: =_xlfn.TEXTJOIN(" ", TRUE, Blad1!B149:C149)
G150: =_xlfn.TEXTJOIN(" ", TRUE, Blad1!B150:C150)
G151: =_xlfn.TEXTJOIN(" ", TRUE, Blad1!B151:C151)
G152: =_xlfn.TEXTJOIN(" ", TRUE, Blad1!B152:C152)
... G231: =_xlfn.TEXTJOIN(" ", TRUE, Blad1!B231:C231)
