Workbook

Sheet names_per_doc
C2: pad_spec | D2: otto_tars | E2: klok_otto | F2: klok_flex | I2: pad_spec | J2: otto_tars | K2: klok_otto | L2: klok_flex | O2: pad_spec | P2: otto_tars | Q2: klok_otto | R2: klok_flex | V2: Padifood specificatie | W2: OTTO -Padifood tarievenoverzicht per persoon - achternaam voornaam | X2: 202549, Kloklijst Padifood, Otto Workforce | Y2: 202550, Kloklijst Padifood, Flexspecialisten
B3: pad_spec | C3: =COUNTIFS($I$3:$I$150, 1, $I$3:$I$150, 1) / COUNTIFS($I$3:$I$150, 1) -> 1 | D3: =COUNTIFS($I$3:$I$150, 1, $J$3:$J$150, 1) / COUNTIFS($I$3:$I$150, 1) -> 0.53125 | E3: =COUNTIFS($I$3:$I$150, 1, $K$3:$K$150, 1) / COUNTIFS($I$3:$I$150, 1) -> 0.96875 | F3: =COUNTIFS($I$3:$I$150, 1, $L$3:$L$150, 1) / COUNTIFS($I$3:$I$150, 1) -> 0 | I3: =COUNTIF(V$3:V$114, O3) -> 0 | J3: =COUNTIF(W$3:W$114, P3) -> 1 | K3: =COUNTIF(X$3:X$114, Q3) -> 0 | L3: =COUNTIF(Y$3:Y$114, R3) -> 0 | O3: {=_xlfn._xlws.SORT(_xlfn.UNIQUE(_xlfn.TOCOL(names_per_doc!$V$3:$Y$150)))} -> Adamska Daria | P3: {=_xlfn._xlws.SORT(_xlfn.UNIQUE(_xlfn.TOCOL(names_per_doc!$V$3:$Y$150)))} -> Adamska Daria | Q3: {=_xlfn._xlws.SORT(_xlfn.UNIQUE(_xlfn.TOCOL(names_per_doc!$V$3:$Y$150)))} -> Adamska Daria | R3: {=_xlfn._xlws.SORT(_xlfn.UNIQUE(_xlfn.TOCOL(names_per_doc!$V$3:$Y$150)))} -> Adamska Daria | V3: Agafitei Ioan | W3: Adamska Daria | X3: Agafitei Ioan | Y3: Babinecz Narcisa Bianca
B4: otto_tars | C4: =COUNTIFS($I$3:$I$150, 1, $J$3:$J$150, 1) / COUNTIFS($J$3:$J$150, 1) -> 0.425 | D4: =COUNTIFS($J$3:$J$150, 1, $J$3:$J$150, 1) / COUNTIFS($J$3:$J$150, 1) -> 1 | E4: =COUNTIFS($J$3:$J$150, 1, $K$3:$K$150, 1) / COUNTIFS($J$3:$J$150, 1) -> 0.4875 | F4: =COUNTIFS($J$3:$J$150, 1, $L$3:$L$150, 1) / COUNTIFS($J$3:$J$150, 1) -> 0 | I4: =COUNTIF(V$3:V$114, O4) -> 1 | J4: =COUNTIF(W$3:W$114, P4) -> 0 | K4: =COUNTIF(X$3:X$114, Q4) -> 1 | L4: =COUNTIF(Y$3:Y$114, R4) -> 0 | O4: Agafitei Ioan | P4: Agafitei Ioan | Q4: Agafitei Ioan | R4: Agafitei Ioan | V4: Artini Paolo | W4: Andryjanczyk Przemyslaw | X4: Artini Paolo | Y4: Baciu Dumitru
B5: klok_otto | C5: =COUNTIFS($I$3:$I$150, 1, $K$3:$K$150, 1) / COUNTIFS($K$3:$K$150, 1) -> 0.80519481 | D5: =COUNTIFS($J$3:$J$150, 1, $K$3:$K$150, 1) / COUNTIFS($K$3:$K$150, 1) -> 0.50649351 | E5: =COUNTIFS($K$3:$K$150, 1, $K$3:$K$150, 1) / COUNTIFS($K$3:$K$150, 1) -> 1 | F5: =COUNTIFS($K$3:$K$150, 1, $L$3:$L$150, 1) / COUNTIFS($K$3:$K$150, 1) -> 0 | I5: =COUNTIF(V$3:V$114, O5) -> 0 | J5: =COUNTIF(W$3:W$114, P5) -> 1 | K5: =COUNTIF(X$3:X$114, Q5) -> 0 | L5: =COUNTIF(Y$3:Y$114, R5) -> 0 | O5: Andryjanczyk Przemyslaw | P5: Andryjanczyk Przemyslaw | Q5: Andryjanczyk Przemyslaw | R5: Andryjanczyk Przemyslaw | V5: Augustinaitis Audrius | W5: Arhipova Inna | X5: Augustinaitis Audrius | Y5: Baran Marcin
B6: klok_flex | C6: =COUNTIFS($I$3:$I$150, 1, $L$3:$L$150, 1) / COUNTIFS($L$3:$L$150, 1) -> 0 | D6: =COUNTIFS($J$3:$J$150, 1, $L$3:$L$150, 1) / COUNTIFS($L$3:$L$150, 1) -> 0 | E6: =COUNTIFS($K$3:$K$150, 1, $L$3:$L$150, 1) / COUNTIFS($L$3:$L$150, 1) -> 0 | F6: =COUNTIFS($L$3:$L$150, 1, $L$3:$L$150, 1) / COUNTIFS($L$3:$L$150, 1) -> 1 | I6: =COUNTIF(V$3:V$114, O6) -> 0 | J6: =COUNTIF(W$3:W$114, P6) -> 1 | K6: =COUNTIF(X$3:X$114, Q6) -> 0 | L6: =COUNTIF(Y$3:Y$114, R6) -> 0 | O6: Arhipova Inna | P6: Arhipova Inna | Q6: Arhipova Inna | R6: Arhipova Inna | V6: Babics David | W6: Babics David | X6: Babics David | Y6: Bernad Maciej
I7: =COUNTIF(V$3:V$114, O7) -> 1 | J7: =COUNTIF(W$3:W$114, P7) -> 0 | K7: =COUNTIF(X$3:X$114, Q7) -> 1 | L7: =COUNTIF(Y$3:Y$114, R7) -> 0 | O7: Artini Paolo | P7: Artini Paolo | Q7: Artini Paolo | R7: Artini Paolo | V7: Baraniuk Beata | W7: Baraniuk Beata | X7: Baraniuk Beata | Y7: Bodykto Kamila Nikola
I8: =COUNTIF(V$3:V$114, O8) -> 1 | J8: =COUNTIF(W$3:W$114, P8) -> 0 | K8: =COUNTIF(X$3:X$114, Q8) -> 1 | L8: =COUNTIF(Y$3:Y$114, R8) -> 0 | O8: Augustinaitis Audrius | P8: Augustinaitis Audrius | Q8: Augustinaitis Audrius | R8: Augustinaitis Audrius | V8: Bienkowska Bernardeta | W8: Baselga Alvarez de Lorenzana Lucia | X8: Bienkowska Bernardeta | Y8: Browarski Marcin
I9: =COUNTIF(V$3:V$114, O9) -> 1 | J9: =COUNTIF(W$3:W$114, P9) -> 1 | K9: =COUNTIF(X$3:X$114, Q9) -> 1 | L9: =COUNTIF(Y$3:Y$114, R9) -> 0 | O9: Babics David | P9: Babics David | Q9: Babics David | R9: Babics David | V9: Bierczak Piotr | W9: Bender Kinga | X9: Bierczak Piotr | Y9: Cotrau Mircea
I10: =COUNTIF(V$3:V$114, O10) -> 0 | J10: =COUNTIF(W$3:W$114, P10) -> 0 | K10: =COUNTIF(X$3:X$114, Q10) -> 0 | L10: =COUNTIF(Y$3:Y$114, R10) -> 1 | O10: Babinecz Narcisa Bianca | P10: Babinecz Narcisa Bianca | Q10: Babinecz Narcisa Bianca | R10: Babinecz Narcisa Bianca | V10: Bruzdzinski Marcel | W10: Bierczak Piotr | X10: Bruzdzinski Marcel | Y10: Czenczek Mateusz
I11: =COUNTIF(V$3:V$114, O11) -> 0 | J11: =COUNTIF(W$3:W$114, P11) -> 0 | K11: =COUNTIF(X$3:X$114, Q11) -> 0 | L11: =COUNTIF(Y$3:Y$114, R11) -> 1 | O11: Baciu Dumitru | P11: Baciu Dumitru | Q11: Baciu Dumitru | R11: Baciu Dumitru | V11: Cabla Robert | W11: Bisliukas Armandas | X11: Cabla Robert | Y11: Da Silva Coelho Stephen Ricardo
I12: =COUNTIF(V$3:V$114, O12) -> 0 | J12: =COUNTIF(W$3:W$114, P12) -> 0 | K12: =COUNTIF(X$3:X$114, Q12) -> 0 | L12: =COUNTIF(Y$3:Y$114, R12) -> 1 | O12: Baran Marcin | P12: Baran Marcin | Q12: Baran Marcin | R12: Baran Marcin | V12: Cieslak Grazyna | W12: Calzado Marin Alvaro | X12: Chlipala Marzena | Y12: Da Silva Figueiredo Laura Alexandra
I13: =COUNTIF(V$3:V$114, O13) -> 1 | J13: =COUNTIF(W$3:W$114, P13) -> 1 | K13: =COUNTIF(X$3:X$114, Q13) -> 1 | L13: =COUNTIF(Y$3:Y$114, R13) -> 0 | O13: Baraniuk Beata | P13: Baraniuk Beata | Q13: Baraniuk Beata | R13: Baraniuk Beata | V13: Colaco Eden | W13: Chlipala Marzena | X13: Cieslak Grazyna | Y13: Dudek Bartosz
I14: =COUNTIF(V$3:V$114, O14) -> 0 | J14: =COUNTIF(W$3:W$114, P14) -> 1 | K14: =COUNTIF(X$3:X$114, Q14) -> 0 | L14: =COUNTIF(Y$3:Y$114, R14) -> 0 | O14: Baselga Alvarez de Lorenzana Lucia | P14: Baselga Alvarez de Lorenzana Lucia | Q14: Baselga Alvarez de Lorenzana Lucia | R14: Baselga Alvarez de Lorenzana Lucia | V14: Costa Pedro | W14: Chwalinska Izabela | X14: Ciutacu 15815800 Iulian | Y14: Firlej Ryszard
I15: =COUNTIF(V$3:V$114, O15) -> 0 | J15: =COUNTIF(W$3:W$114, P15) -> 1 | K15: =COUNTIF(X$3:X$114, Q15) -> 0 | L15: =COUNTIF(Y$3:Y$114, R15) -> 0 | O15: Bender Kinga | P15: Bender Kinga | Q15: Bender Kinga | R15: Bender Kinga | V15: Cotofrea Stefan-Bogdan | W15: Cimoszko Adam | X15: Colaco Eden | Y15: Franczok Andrzej
I16: =COUNTIF(V$3:V$114, O16) -> 0 | J16: =COUNTIF(W$3:W$114, P16) -> 0 | K16: =COUNTIF(X$3:X$114, Q16) -> 0 | L16: =COUNTIF(Y$3:Y$114, R16) -> 1 | O16: Bernad Maciej | P16: Bernad Maciej | Q16: Bernad Maciej | R16: Bernad Maciej | V16: Cristu Virgil | W16: Cimponer Georgiana | X16: Costa Pedro | Y16: Gagaitis Karolis
I17: =COUNTIF(V$3:V$114, O17) -> 1 | J17: =COUNTIF(W$3:W$114, P17) -> 0 | K17: =COUNTIF(X$3:X$114, Q17) -> 1 | L17: =COUNTIF(Y$3:Y$114, R17) -> 0 | O17: Bienkowska Bernardeta | P17: Bienkowska Bernardeta | Q17: Bienkowska Bernardeta | R17: Bienkowska Bernardeta | V17: Cwioro Agnieszka | W17: Ciszewska Aleksandra | X17: Costa Vinhas Elisabete Filipa | Y17: Gryglik Katarzyna
I18: =COUNTIF(V$3:V$114, O18) -> 1 | J18: =COUNTIF(W$3:W$114, P18) -> 1 | K18: =COUNTIF(X$3:X$114, Q18) -> 1 | L18: =COUNTIF(Y$3:Y$114, R18) -> 0 | O18: Bierczak Piotr | P18: Bierczak Piotr | Q18: Bierczak Piotr | R18: Bierczak Piotr | V18: Czajkowski Jaroslaw | W18: Ciz David | X18: Cotofrea Stefan-Bogdan | Y18: Guilherme Victorino
... I64: =COUNTIF(V$3:V$114, O64) -> 0 | J64: =COUNTIF(W$3:W$114, P64) -> 1 | K64: =COUNTIF(X$3:X$114, Q64) -> 0 | L64: =COUNTIF(Y$3:Y$114, R64) -> 0 | O64: Garcia Ocampo Alejandro | P64: Garcia Ocampo Alejandro | Q64: Garcia Ocampo Alejandro | R64: Garcia Ocampo Alejandro | V64: Marques Wilson | W64: Kozel Peter | X64: Kwiecinska Patrycja | Y64: Wypych Piotr
I65: =COUNTIF(V$3:V$114, O65) -> 1 | J65: =COUNTIF(W$3:W$114, P65) -> 0 | K65: =COUNTIF(X$3:X$114, Q65) -> 1 | L65: =COUNTIF(Y$3:Y$114, R65) -> 0 | O65: Gigliotti Mario | P65: Gigliotti Mario | Q65: Gigliotti Mario | R65: Gigliotti Mario | V65: Matiscik Vladimir | W65: Kozlowski Tomasz | X65: Lenart Richard
I66: =COUNTIF(V$3:V$114, O66) -> 1 | J66: =COUNTIF(W$3:W$114, P66) -> 0 | K66: =COUNTIF(X$3:X$114, Q66) -> 1 | L66: =COUNTIF(Y$3:Y$114, R66) -> 0 | O66: Gil Sandra | P66: Gil Sandra | Q66: Gil Sandra | R66: Gil Sandra | V66: Michalik Kamil | W66: Kulak Anna | X66: Lopusiewicz Maciej
I67: =COUNTIF(V$3:V$114, O67) -> 0 | J67: =COUNTIF(W$3:W$114, P67) -> 0 | K67: =COUNTIF(X$3:X$114, Q67) -> 1 | L67: =COUNTIF(Y$3:Y$114, R67) -> 0 | O67: Glabien Dariusz | P67: Glabien Dariusz | Q67: Glabien Dariusz | R67: Glabien Dariusz | V67: Mika Patrycja | W67: Kupcikova Iva | X67: Madej Marta
I68: =COUNTIF(V$3:V$114, O68) -> 1 | J68: =COUNTIF(W$3:W$114, P68) -> 1 | K68: =COUNTIF(X$3:X$114, Q68) -> 0 | L68: =COUNTIF(Y$3:Y$114, R68) -> 0 | O68: Glabien Dariusz | P68: Glabien Dariusz | Q68: Glabien Dariusz | R68: Glabien Dariusz | V68: Mikiciuk Tomasz | W68: Kutermak Dawid | X68: Madry Oliwier
I69: =COUNTIF(V$3:V$114, O69) -> 0 | J69: =COUNTIF(W$3:W$114, P69) -> 0 | K69: =COUNTIF(X$3:X$114, Q69) -> 1 | L69: =COUNTIF(Y$3:Y$114, R69) -> 0 | O69: Gracia Juarez Juan | P69: Gracia Juarez Juan | Q69: Gracia Juarez Juan | R69: Gracia Juarez Juan | V69: Mikulska Anna | W69: Kutkiewicz Katarzyna | X69: Madry Slawomir
I70: =COUNTIF(V$3:V$114, O70) -> 1 | J70: =COUNTIF(W$3:W$114, P70) -> 1 | K70: =COUNTIF(X$3:X$114, Q70) -> 1 | L70: =COUNTIF(Y$3:Y$114, R70) -> 0 | O70: Grucelski Marcin | P70: Grucelski Marcin | Q70: Grucelski Marcin | R70: Grucelski Marcin | V70: Milon Oliwia | W70: Kwiecinska Patrycja | X70: Major Aleks
I71: =COUNTIF(V$3:V$114, O71) -> 0 | J71: =COUNTIF(W$3:W$114, P71) -> 0 | K71: =COUNTIF(X$3:X$114, Q71) -> 0 | L71: =COUNTIF(Y$3:Y$114, R71) -> 1 | O71: Gryglik Katarzyna | P71: Gryglik Katarzyna | Q71: Gryglik Katarzyna | R71: Gryglik Katarzyna | V71: Mladinovici Marius | W71: Lenart Richard | X71: Major Daria
I72: =COUNTIF(V$3:V$114, O72) -> 0 | J72: =COUNTIF(W$3:W$114, P72) -> 0 | K72: =COUNTIF(X$3:X$114, Q72) -> 0 | L72: =COUNTIF(Y$3:Y$114, R72) -> 1 | O72: Guilherme Victorino | P72: Guilherme Victorino | Q72: Guilherme Victorino | R72: Guilherme Victorino | V72: Mlot Wiktoria | W72: Lopez Ventura Daniel | X72: Maka Patryk
I73: =COUNTIF(V$3:V$114, O73) -> 0 | J73: =COUNTIF(W$3:W$114, P73) -> 0 | K73: =COUNTIF(X$3:X$114, Q73) -> 0 | L73: =COUNTIF(Y$3:Y$114, R73) -> 1 | O73: Hagiu Elena Cristina | P73: Hagiu Elena Cristina | Q73: Hagiu Elena Cristina | R73: Hagiu Elena Cristina | V73: Mlynarczyk Bogumil | W73: Madej Marta | X73: Mankowska Paulina
I74: =COUNTIF(V$3:V$114, O74) -> 0 | J74: =COUNTIF(W$3:W$114, P74) -> 1 | K74: =COUNTIF(X$3:X$114, Q74) -> 0 | L74: =COUNTIF(Y$3:Y$114, R74) -> 0 | O74: Hajduk Lukasz | P74: Hajduk Lukasz | Q74: Hajduk Lukasz | R74: Hajduk Lukasz | V74: Mogilnicki Konrad | W74: Madry Slawomir | X74: Marco Ales
I75: =COUNTIF(V$3:V$114, O75) -> 0 | J75: =COUNTIF(W$3:W$114, P75) -> 1 | K75: =COUNTIF(X$3:X$114, Q75) -> 0 | L75: =COUNTIF(Y$3:Y$114, R75) -> 0 | O75: Hanus Branislav | P75: Hanus Branislav | Q75: Hanus Branislav | R75: Hanus Branislav | V75: Moldovan Adrian | W75: Major Daria | X75: Marczak Beata
I76: =COUNTIF(V$3:V$114, O76) -> 0 | J76: =COUNTIF(W$3:W$114, P76) -> 1 | K76: =COUNTIF(X$3:X$114, Q76) -> 1 | L76: =COUNTIF(Y$3:Y$114, R76) -> 0 | O76: Holubowska Barbara | P76: Holubowska Barbara | Q76: Holubowska Barbara | R76: Holubowska Barbara | V76: Muc Jerzy | W76: Maksin Lubos | X76: Marek Magdalena
... I113: =COUNTIF(V$3:V$114, O113) -> 1 | J113: =COUNTIF(W$3:W$114, P113) -> 1 | K113: =COUNTIF(X$3:X$114, Q113) -> 1 | L113: =COUNTIF(Y$3:Y$114, R113) -> 0 | O113: Kosior Agnieszka | P113: Kosior Agnieszka | Q113: Kosior Agnieszka | R113: Kosior Agnieszka | V113: Zmijewska Magdalena | W113: Przydatek Renata | X113: Sapa Daniel
I114: =COUNTIF(V$3:V$114, O114) -> 1 | J114: =COUNTIF(W$3:W$114, P114) -> 0 | K114: =COUNTIF(X$3:X$114, Q114) -> 1 | L114: =COUNTIF(Y$3:Y$114, R114) -> 0 | O114: Koson Adrian | P114: Koson Adrian | Q114: Koson Adrian | R114: Koson Adrian | W114: Raduceanu Razvan | X114: Seciu Marius
I115: =COUNTIF(V$3:V$114, O115) -> 1 | J115: =COUNTIF(W$3:W$114, P115) -> 1 | K115: =COUNTIF(X$3:X$114, Q115) -> 1 | L115: =COUNTIF(Y$3:Y$114, R115) -> 0 | O115: Koszny Ewa | P115: Koszny Ewa | Q115: Koszny Ewa | R115: Koszny Ewa | W115: Recka Anna | X115: Skorczewski Dawid
I116: =COUNTIF(V$3:V$114, O116) -> 1 | J116: =COUNTIF(W$3:W$114, P116) -> 1 | K116: =COUNTIF(X$3:X$114, Q116) -> 1 | L116: =COUNTIF(Y$3:Y$114, R116) -> 0 | O116: Kovacova Martina | P116: Kovacova Martina | Q116: Kovacova Martina | R116: Kovacova Martina | W116: Rogalska Agnieszka | X116: Skrzypczak Kewin
I117: =COUNTIF(V$3:V$114, O117) -> 0 | J117: =COUNTIF(W$3:W$114, P117) -> 0 | K117: =COUNTIF(X$3:X$114, Q117) -> 0 | L117: =COUNTIF(Y$3:Y$114, R117) -> 1 | O117: Kowalkowski Dominik Janusz | P117: Kowalkowski Dominik Janusz | Q117: Kowalkowski Dominik Janusz | R117: Kowalkowski Dominik Janusz | W117: Rusnik Edward | X117: Slepcik Ernesto
I118: =COUNTIF(V$3:V$114, O118) -> 0 | J118: =COUNTIF(W$3:W$114, P118) -> 0 | K118: =COUNTIF(X$3:X$114, Q118) -> 0 | L118: =COUNTIF(Y$3:Y$114, R118) -> 1 | O118: Koza Lukasz | P118: Koza Lukasz | Q118: Koza Lukasz | R118: Koza Lukasz | W118: Skrzypczak Kewin | X118: Slosiar Tomas
I119: =COUNTIF(V$3:V$114, O119) -> 0 | J119: =COUNTIF(W$3:W$114, P119) -> 1 | K119: =COUNTIF(X$3:X$114, Q119) -> 0 | L119: =COUNTIF(Y$3:Y$114, R119) -> 0 | O119: Kozel Peter | P119: Kozel Peter | Q119: Kozel Peter | R119: Kozel Peter | W119: Slosiar Tomas | X119: Solomonova Nikola
I120: =COUNTIF(V$3:V$114, O120) -> 0 | J120: =COUNTIF(W$3:W$114, P120) -> 1 | K120: =COUNTIF(X$3:X$114, Q120) -> 0 | L120: =COUNTIF(Y$3:Y$114, R120) -> 0 | O120: Kozlowski Tomasz | P120: Kozlowski Tomasz | Q120: Kozlowski Tomasz | R120: Kozlowski Tomasz | W120: Smug Piotr | X120: Stankiewicz Lucyna
I121: =COUNTIF(V$3:V$114, O121) -> 1 | J121: =COUNTIF(W$3:W$114, P121) -> 0 | K121: =COUNTIF(X$3:X$114, Q121) -> 1 | L121: =COUNTIF(Y$3:Y$114, R121) -> 0 | O121: Kristof Jakub | P121: Kristof Jakub | Q121: Kristof Jakub | R121: Kristof Jakub | W121: Solomonova Nikola | X121: Stencel Katarzyna
I122: =COUNTIF(V$3:V$114, O122) -> 0 | J122: =COUNTIF(W$3:W$114, P122) -> 1 | K122: =COUNTIF(X$3:X$114, Q122) -> 0 | L122: =COUNTIF(Y$3:Y$114, R122) -> 0 | O122: Kulak Anna | P122: Kulak Anna | Q122: Kulak Anna | R122: Kulak Anna | W122: Sott Michal | X122: Strzalek Cezary
...

Sheet kloklijsten
D3: 0
C4: Agafitei Ioan
C5: Artini Paolo | D5: Agafitei Ioan
C6: Augustinaitis Audrius | D6: Artini Paolo
C7: Babics David | D7: Augustinaitis Audrius
C8: Baraniuk Beata | D8: Babics David
C9: Bienkowska Bernardeta | D9: Baraniuk Beata
C10: Bierczak Piotr | D10: Bienkowska Bernardeta
C11: Bruzdzinski Marcel | D11: Bierczak Piotr
C12: Cabla Robert | D12: Bruzdzinski Marcel
C13: Chlipala Marzena | D13: Cabla Robert
C14: Cieslak Grazyna | D14: Chlipala Marzena
C15: Ciutacu 15815800 Iulian | D15: Cieslak Grazyna
C16: Colaco Eden | D16: Ciutacu 15815800 Iulian
... C123: Zmijewska Magdalena | D123: Stencel Katarzyna
C124: 0 | D124: Strzalek Cezary
D125: Sztabinska Anna
C126: Agafitei Ioan | D126: Szulewska Dorota
C127: Artini Paolo | D127: Tranevicius Martynas
C128: Augustinaitis Audrius | D128: Urbanowicz Malgorzata
C129: Babics David | D129: Ustrzynski Jakub
C130: Baraniuk Beata | D130: Wach Piotr
C131: Bienkowska Bernardeta | D131: Wajler Kamila
C132: Bierczak Piotr | D132: Wielgus Mateusz
C133: Bruzdzinski Marcel | D133: Wilczak Daniel
C134: Cabla Robert | D134: Wolanin Maciej
C135: Chlipala Marzena | D135: Zaremba Przemyslaw
C136: Cieslak Grazyna | D136: Ziolkowska Agnieszka
C137: Colaco Eden | D137: Zmijewska Magdalena
C138: Costa Pedro | D138: 0
C139: Costa Vinhas Elisabete Filipa
C140: Cotofrea Stefan-Bogdan
C141: Cristu Virgil
C142: Cwioro Agnieszka
C143: Cyran Anna
C144: Czajkowski Jaroslaw
C145: Dalalau Gabriel
C146: Dekanova Katarina
C147: Dlugolecki Grzegorz
C148: Domaradzka Jagoda
...

Sheet unique_names
B2: {=_xlfn._xlws.SORT(_xlfn.UNIQUE(_xlfn.TOCOL(names_per_doc!$V$3:$Y$150)))} -> Adamska Daria | C2: {=_xlfn._xlws.SORT(_xlfn.UNIQUE(_xlfn.TOCOL(names_per_doc!$V$3:$Y$150)))} -> Adamska Daria | D2: {=_xlfn._xlws.SORT(_xlfn.UNIQUE(_xlfn.TOCOL(names_per_doc!$V$3:$Y$150)))} -> Adamska Daria | E2: {=_xlfn._xlws.SORT(_xlfn.UNIQUE(_xlfn.TOCOL(names_per_doc!$V$3:$Y$150)))} -> Adamska Daria
B3: Agafitei Ioan | C3: Agafitei Ioan | D3: Agafitei Ioan | E3: Agafitei Ioan
B4: Andryjanczyk Przemyslaw | C4: Andryjanczyk Przemyslaw | D4: Andryjanczyk Przemyslaw | E4: Andryjanczyk Przemyslaw
B5: Arhipova Inna | C5: Arhipova Inna | D5: Arhipova Inna | E5: Arhipova Inna
B6: Artini Paolo | C6: Artini Paolo | D6: Artini Paolo | E6: Artini Paolo
B7: Augustinaitis Audrius | C7: Augustinaitis Audrius | D7: Augustinaitis Audrius | E7: Augustinaitis Audrius
B8: Babics David | C8: Babics David | D8: Babics David | E8: Babics David
B9: Babinecz Narcisa Bianca | C9: Babinecz Narcisa Bianca | D9: Babinecz Narcisa Bianca | E9: Babinecz Narcisa Bianca
B10: Baciu Dumitru | C10: Baciu Dumitru | D10: Baciu Dumitru | E10: Baciu Dumitru
B11: Baran Marcin | C11: Baran Marcin | D11: Baran Marcin | E11: Baran Marcin
B12: Baraniuk Beata | C12: Baraniuk Beata | D12: Baraniuk Beata | E12: Baraniuk Beata
B13: Baselga Alvarez de Lorenzana Lucia | C13: Baselga Alvarez de Lorenzana Lucia | D13: Baselga Alvarez de Lorenzana Lucia | E13: Baselga Alvarez de Lorenzana Lucia
B14: Bender Kinga | C14: Bender Kinga | D14: Bender Kinga | E14: Bender Kinga
... B272: Zmijewska Magdalena | C272: Zmijewska Magdalena | D272: Zmijewska Magdalena | E272: Zmijewska Magdalena
B273: 0 | C273: 0 | D273: 0 | E273: 0
